Workbook

Sheet Clean
A1: แผน/บันทึกการบำรุงรักษาเครื่องมือและห้องสะอาด (วัน)
A2: ชื่อเครื่องมือ | B2: - | H2: รหัส | M2: สถานที่ | O2: Zone A | T2: ปี | U2: 2569 | W2: ผู้รับผิดชอบ | Z2: (ตามเวรบรรจุ)
A3: รายการ | B3: เดือน | C3: เดือน กรกฎาคม
A4: (ความถี่) | B4: วันที่ | C4: 1 | D4: 2 | E4: 3 | F4: 4 | G4: 5 | H4: 6 | I4: 7 | J4: 8 | K4: 9 | L4: 10 | M4: 11 | N4: 12 | O4: 13 | P4: 14 | Q4: 15 | R4: 16 | S4: 17 | T4: 18 | U4: 19 | V4: 20 | W4: 21 | X4: 22 | Y4: 23 | Z4: 24 | AA4: 25 | AB4: 26 | AC4: 27 | AD4: 28 | AE4: 29 | AF4: 30 | AG4: 31
B5: น้ำยาฆ่าเชื้อ | C5: =_xlfn.IFNA(IF(OR(C4="",C4=0),"",(VLOOKUP($B5,'น้ำยา-เครื่อง'!$A:$AF,C4+1,FALSE))),"") -> 1 | D5: =_xlfn.IFNA(IF(OR(D4="",D4=0),"",(VLOOKUP($B5,'น้ำยา-เครื่อง'!$A:$AF,D4+1,FALSE))),"") -> 1 | E5: =_xlfn.IFNA(IF(OR(E4="",E4=0),"",(VLOOKUP($B5,'น้ำยา-เครื่อง'!$A:$AF,E4+1,FALSE))),"") -> 1 | F5: =_xlfn.IFNA(IF(OR(F4="",F4=0),"",(VLOOKUP($B5,'น้ำยา-เครื่อง'!$A:$AF,F4+1,FALSE))),"") -> 0 | G5: =_xlfn.IFNA(IF(OR(G4="",G4=0),"",(VLOOKUP($B5,'น้ำยา-เครื่อง'!$A:$AF,G4+1,FALSE))),"") -> 0 | H5: =_xlfn.IFNA(IF(OR(H4="",H4=0),"",(VLOOKUP($B5,'น้ำยา-เครื่อง'!$A:$AF,H4+1,FALSE))),"") -> 2 | I5: =_xlfn.IFNA(IF(OR(I4="",I4=0),"",(VLOOKUP($B5,'น้ำยา-เครื่อง'!$A:$AF,I4+1,FALSE))),"") -> 2 | J5: =_xlfn.IFNA(IF(OR(J4="",J4=0),"",(VLOOKUP($B5,'น้ำยา-เครื่อง'!$A:$AF,J4+1,FALSE))),"") -> 2 | ... AG5: =_xlfn.IFNA(IF(OR(AG4="",AG4=0),"",(VLOOKUP($B5,'น้ำยา-เครื่อง'!$A:$AF,AG4+1,FALSE))),"") -> 1
A6: Stick roller, เช็คถูทำความสะอาดพื้นห้อง (วันที่ใช้งาน) | B6: แผน | C6: O | I6: O | J6: O | K6: O | P6: O | Q6: O | R6: O | W6: O | X6: O | Y6: O
B7: ผู้ปฏิบัติ
B9: แผน
B10: ผู้ปฏิบัติ
B12: แผน
B13: ผู้ปฏิบัติ
A15: รายการ | B15: เดือน | C15: เดือน สิงหาคม
A16: (ความถี่) | B16: วันที่ | C16: 1 | D16: 2 | E16: 3 | F16: 4 | G16: 5 | H16: 6 | I16: 7 | J16: 8 | K16: 9 | L16: 10 | M16: 11 | N16: 12 | O16: 13 | P16: 14 | Q16: 15 | R16: 16 | S16: 17 | T16: 18 | U16: 19 | V16: 20 | W16: 21 | X16: 22 | Y16: 23 | Z16: 24 | AA16: 25 | AB16: 26 | AC16: 27 | AD16: 28 | AE16: 29 | AF16: 30 | AG16: 31
B17: น้ำยาฆ่าเชื้อ | C17: =_xlfn.IFNA(IF(OR(C16="",C16=0),"",(VLOOKUP($B17,'น้ำยา-เครื่อง'!$AH:$BM,C16+1,FALSE))),"") -> 0 | D17: =_xlfn.IFNA(IF(OR(D16="",D16=0),"",(VLOOKUP($B17,'น้ำยา-เครื่อง'!$AH:$BM,D16+1,FALSE))),"") -> 0 | E17: =_xlfn.IFNA(IF(OR(E16="",E16=0),"",(VLOOKUP($B17,'น้ำยา-เครื่อง'!$AH:$BM,E16+1,FALSE))),"") -> 2 | F17: =_xlfn.IFNA(IF(OR(F16="",F16=0),"",(VLOOKUP($B17,'น้ำยา-เครื่อง'!$AH:$BM,F16+1,FALSE))),"") -> 2 | G17: =_xlfn.IFNA(IF(OR(G16="",G16=0),"",(VLOOKUP($B17,'น้ำยา-เครื่อง'!$AH:$BM,G16+1,FALSE))),"") -> 2 | H17: =_xlfn.IFNA(IF(OR(H16="",H16=0),"",(VLOOKUP($B17,'น้ำยา-เครื่อง'!$AH:$BM,H16+1,FALSE))),"") -> 2 | I17: =_xlfn.IFNA(IF(OR(I16="",I16=0),"",(VLOOKUP($B17,'น้ำยา-เครื่อง'!$AH:$BM,I16+1,FALSE))),"") -> 2 | J17: =_xlfn.IFNA(IF(OR(J16="",J16=0),"",(VLOOKUP($B17,'น้ำยา-เครื่อง'!$AH:$BM,J16+1,FALSE))),"") -> 0 | ... AG17: =_xlfn.IFNA(IF(OR(AG16="",AG16=0),"",(VLOOKUP($B17,'น้ำยา-เครื่อง'!$AH:$BM,AG16+1,FALSE))),"") -> 2
A18: =IF(A6="","",A6) -> Stick roller, เช็คถูทำความสะอาดพื้นห้อง (วันที่ใช้งาน) | B18: แผน | F18: O | G18: O | H18: O | O18: O | P18: O | T18: O | U18: O | V18: O | AA18: O | AB18: O
B19: ผู้ปฏิบัติ
A21: =IF(A9="","",A9) | B21: แผน
B22: ผู้ปฏิบัติ
A24: =IF(A12="","",A12) | B24: แผน
B25: ผู้ปฏิบัติ
A27: หมายเหตุ วงกลม (O) หมายถึง สัปดาห์ที่ต้องทำการบำรุงรักษาเครื่องมือหรือห้องสะอาด เมื่อดำเนินการตามแผนแล้ว ให้ทำเครื่องหมายถูก (ü) ในวงกลมที่ระบุ | W27: น้ำยาฆ่าเชื้อ (1) Chlorhex - C (2) Benz Cl
P29: จัดทำโดย | R29: พีรวัส | U29: อนุมัติโดย | W29: วรพงศ์ | Z29: วันที่ | AA29: 244531
A31: แผน/บันทึกการบำรุงรักษาเครื่องมือและห้องสะอาด (วัน)
A32: ชื่อเครื่องมือ | B32: - | H32: รหัส | M32: สถานที่ | O32: Zone B & C (ไม่รวมห้องแต่งตัว | T32: ปี | U32: =$U$2 -> 2569 | W32: ผู้รับผิดชอบ | Z32: (ตามเวรทำความสะอาด)
A33: รายการ | B33: เดือน | C33: =C3 -> เดือน กรกฎาคม
A34: (ความถี่) | B34: วันที่ | C34: =C4 -> 1 | D34: =D4 -> 2 | E34: =E4 -> 3 | F34: =F4 -> 4 | G34: =G4 -> 5 | H34: =H4 -> 6 | I34: =I4 -> 7 | J34: =J4 -> 8 | ... AG34: =AG4 -> 31
B35: น้ำยาฆ่าเชื้อ | C35: =_xlfn.IFNA(IF(OR(C34="",C34=0),"",(VLOOKUP($B35,'น้ำยา-เครื่อง'!$A:$AF,C34+1,FALSE))),"") -> 1 | D35: =_xlfn.IFNA(IF(OR(D34="",D34=0),"",(VLOOKUP($B35,'น้ำยา-เครื่อง'!$A:$AF,D34+1,FALSE))),"") -> 1 | E35: =_xlfn.IFNA(IF(OR(E34="",E34=0),"",(VLOOKUP($B35,'น้ำยา-เครื่อง'!$A:$AF,E34+1,FALSE))),"") -> 1 | F35: =_xlfn.IFNA(IF(OR(F34="",F34=0),"",(VLOOKUP($B35,'น้ำยา-เครื่อง'!$A:$AF,F34+1,FALSE))),"") -> 0 | G35: =_xlfn.IFNA(IF(OR(G34="",G34=0),"",(VLOOKUP($B35,'น้ำยา-เครื่อง'!$A:$AF,G34+1,FALSE))),"") -> 0 | H35: =_xlfn.IFNA(IF(OR(H34="",H34=0),"",(VLOOKUP($B35,'น้ำยา-เครื่อง'!$A:$AF,H34+1,FALSE))),"") -> 2 | I35: =_xlfn.IFNA(IF(OR(I34="",I34=0),"",(VLOOKUP($B35,'น้ำยา-เครื่อง'!$A:$AF,I34+1,FALSE))),"") -> 2 | J35: =_xlfn.IFNA(IF(OR(J34="",J34=0),"",(VLOOKUP($B35,'น้ำยา-เครื่อง'!$A:$AF,J34+1,FALSE))),"") -> 2 | ... AG35: =_xlfn.IFNA(IF(OR(AG34="",AG34=0),"",(VLOOKUP($B35,'น้ำยา-เครื่อง'!$A:$AF,AG34+1,FALSE))),"") -> 1
A36: Stick roller, เช็คถูทำความสะอาดพื้นห้อง (วันที่ใช้งาน) | B36: แผน | C36: =IF(OR(C35=1,C35=2),"O","") -> O | D36: =IF(OR(D35=1,D35=2),"O","") -> O | E36: =IF(OR(E35=1,E35=2),"O","") -> O | F36: =IF(OR(F35=1,F35=2),"O","") | G36: =IF(OR(G35=1,G35=2),"O","") | H36: =IF(OR(H35=1,H35=2),"O","") -> O | I36: =IF(OR(I35=1,I35=2),"O","") -> O | J36: =IF(OR(J35=1,J35=2),"O","") -> O | ... AG36: =IF(OR(AG35=1,AG35=2),"O","") -> O
B37: ผู้ปฏิบัติ
B39: แผน
B40: ผู้ปฏิบัติ
B42: แผน
B43: ผู้ปฏิบัติ
A45: รายการ | B45: เดือน | C45: =C15 -> เดือน สิงหาคม
A46: (ความถี่) | B46: วันที่ | C46: =C16 -> 1 | D46: =D16 -> 2 | E46: =E16 -> 3 | F46: =F16 -> 4 | G46: =G16 -> 5 | H46: =H16 -> 6 | I46: =I16 -> 7 | J46: =J16 -> 8 | ... AG46: =AG16 -> 31
B47: น้ำยาฆ่าเชื้อ | C47: =_xlfn.IFNA(IF(OR(C46="",C46=0),"",(VLOOKUP($B47,'น้ำยา-เครื่อง'!$AH:$BM,C46+1,FALSE))),"") -> 0 | D47: =_xlfn.IFNA(IF(OR(D46="",D46=0),"",(VLOOKUP($B47,'น้ำยา-เครื่อง'!$AH:$BM,D46+1,FALSE))),"") -> 0 | E47: =_xlfn.IFNA(IF(OR(E46="",E46=0),"",(VLOOKUP($B47,'น้ำยา-เครื่อง'!$AH:$BM,E46+1,FALSE))),"") -> 2 | F47: =_xlfn.IFNA(IF(OR(F46="",F46=0),"",(VLOOKUP($B47,'น้ำยา-เครื่อง'!$AH:$BM,F46+1,FALSE))),"") -> 2 | G47: =_xlfn.IFNA(IF(OR(G46="",G46=0),"",(VLOOKUP($B47,'น้ำยา-เครื่อง'!$AH:$BM,G46+1,FALSE))),"") -> 2 | H47: =_xlfn.IFNA(IF(OR(H46="",H46=0),"",(VLOOKUP($B47,'น้ำยา-เครื่อง'!$AH:$BM,H46+1,FALSE))),"") -> 2 | I47: =_xlfn.IFNA(IF(OR(I46="",I46=0),"",(VLOOKUP($B47,'น้ำยา-เครื่อง'!$AH:$BM,I46+1,FALSE))),"") -> 2 | J47: =_xlfn.IFNA(IF(OR(J46="",J46=0),"",(VLOOKUP($B47,'น้ำยา-เครื่อง'!$AH:$BM,J46+1,FALSE))),"") -> 0 | ... AG47: =_xlfn.IFNA(IF(OR(AG46="",AG46=0),"",(VLOOKUP($B47,'น้ำยา-เครื่อง'!$AH:$BM,AG46+1,FALSE))),"") -> 2
A48: =IF(A36="","",A36) -> Stick roller, เช็คถูทำความสะอาดพื้นห้อง (วันที่ใช้งาน) | B48: แผน | C48: =IF(OR(C47=1,C47=2),"O","") | D48: =IF(OR(D47=1,D47=2),"O","") | E48: =IF(OR(E47=1,E47=2),"O","") -> O | F48: =IF(OR(F47=1,F47=2),"O","") -> O | G48: =IF(OR(G47=1,G47=2),"O","") -> O | H48: =IF(OR(H47=1,H47=2),"O","") -> O | I48: =IF(OR(I47=1,I47=2),"O","") -> O | J48: =IF(OR(J47=1,J47=2),"O","") | ... AG48: =IF(OR(AG47=1,AG47=2),"O","") -> O
B49: ผู้ปฏิบัติ
A51: =IF(A39="","",A39) | B51: แผน
B52: ผู้ปฏิบัติ
...

Sheet Monitor
A1: แผน/บันทึกการบำรุงรักษาเครื่องมือและห้องสะอาด (วัน)
A2: ชื่อเครื่องมือ | B2: - | H2: รหัส | I2: - | M2: สถานที่ | O2: ห้องชั่งสารเคมี | T2: ปี | U2: 2569 | W2: ผู้รับผิดชอบ | Z2: เภสัชกร
A3: รายการ | B3: เดือน | C3: =Clean!C3 -> เดือน กรกฎาคม
A4: (ความถี่) | B4: วันที่ | C4: 1 | D4: 2 | E4: 3 | F4: 4 | G4: 5 | H4: 6 | I4: 7 | J4: 8 | K4: 9 | L4: 10 | M4: 11 | N4: 12 | O4: 13 | P4: 14 | Q4: 15 | R4: 16 | S4: 17 | T4: 18 | U4: 19 | V4: 20 | W4: 21 | X4: 22 | Y4: 23 | Z4: 24 | AA4: 25 | AB4: 26 | AC4: 27 | AD4: 28 | AE4: 29 | AF4: 30 | AG4: 31
B5: น้ำยาฆ่าเชื้อ | C5: =Clean!C35 -> 1 | D5: =Clean!D35 -> 1 | E5: =Clean!E35 -> 1 | F5: =Clean!F35 -> 0 | G5: =Clean!G35 -> 0 | H5: =Clean!H35 -> 2 | I5: =Clean!I35 -> 2 | J5: =Clean!J35 -> 2 | ... AG5: =Clean!AG35 -> 1
A6: บันทึกความดันห้อง (เกณฑ์ 0.09-0.13) (ทุกวันที่ชั่งสารเคมี) | B6: แผน
B7: ผู้ปฏิบัติ
B8: ผล
A9: บันทึกอุณหภูมิ (เกณฑ์ 18-24 C) (ทุกวันที่ชั่งสารเคมี) | B9: แผน
B10: ผู้ปฏิบัติ
B11: ผล
A12: บันทึกความชื้นห้อง (เกณฑ์ 40-60%RH) (ทุกวันที่ชั่งสารเคมี) | B12: แผน
B13: ผู้ปฏิบัติ
B14: ผล
A15: รายการ | B15: เดือน | C15: =Clean!C15 -> เดือน สิงหาคม
A16: (ความถี่) | B16: วันที่ | C16: 1 | D16: 2 | E16: 3 | F16: 4 | G16: 5 | H16: 6 | I16: 7 | J16: 8 | K16: 9 | L16: 10 | M16: 11 | N16: 12 | O16: 13 | P16: 14 | Q16: 15 | R16: 16 | S16: 17 | T16: 18 | U16: 19 | V16: 20 | W16: 21 | X16: 22 | Y16: 23 | Z16: 24 | AA16: 25 | AB16: 26 | AC16: 27 | AD16: 28 | AE16: 29 | AF16: 30 | AG16: =Clean!AG16 -> 31
B17: น้ำยา | C17: =Clean!C47 -> 0 | D17: =Clean!D47 -> 0 | E17: =Clean!E47 -> 2 | F17: =Clean!F47 -> 2 | G17: =Clean!G47 -> 2 | H17: =Clean!H47 -> 2 | I17: =Clean!I47 -> 2 | J17: =Clean!J47 -> 0 | ... AG17: =Clean!AG47 -> 2
A18: =IF(A6="","",A6) -> บันทึกความดันห้อง (เกณฑ์ 0.09-0.13) (ทุกวันที่ชั่งสารเคมี) | B18: แผน
B19: ผู้ปฏิบัติ
B20: ผล
A21: =IF(A9="","",A9) -> บันทึกอุณหภูมิ (เกณฑ์ 18-24 C) (ทุกวันที่ชั่งสารเคมี) | B21: แผน
B22: ผู้ปฏิบัติ
B23: ผล
A24: =IF(A12="","",A12) -> บันทึกความชื้นห้อง (เกณฑ์ 40-60%RH) (ทุกวันที่ชั่งสารเคมี) | B24: แผน
B25: ผู้ปฏิบัติ
B26: ผล
A27: หมายเหตุ วงกลม (O) หมายถึง สัปดาห์ที่ต้องทำการบำรุงรักษาเครื่องมือหรือห้องสะอาด เมื่อดำเนินการตามแผนแล้ว ให้ทำเครื่องหมายถูก (ü) ในวงกลมที่ระบุ | W27: น้ำยาฆ่าเชื้อ (1) Chlorhex - C (2) Benz Cl
P29: จัดทำโดย | R29: พีรวัส | U29: อนุมัติโดย | W29: วรพงศ์ | Z29: วันที่ | AA29: =Clean!AA29 -> 244531
A31: แผน/บันทึกการบำรุงรักษาเครื่องมือและห้องสะอาด (วัน)
A32: ชื่อเครื่องมือ | B32: - | H32: - | I32: - | M32: สถานที่ | O32: ห้องเชื่อม Pouch | T32: ปี | U32: =U2 -> 2569 | W32: ผู้รับผิดชอบ | Z32: (ตามเวรบรรจุ)
A33: รายการ | B33: เดือน | C33: =C3 -> เดือน กรกฎาคม
A34: (ความถี่) | B34: วันที่ | C34: =C4 -> 1 | D34: =D4 -> 2 | E34: =E4 -> 3 | F34: =F4 -> 4 | G34: =G4 -> 5 | H34: =H4 -> 6 | I34: =I4 -> 7 | J34: =J4 -> 8 | ... AG34: =AG4 -> 31
B35: น้ำยาฆ่าเชื้อ | C35: =Clean!C5 -> 1 | D35: =Clean!D5 -> 1 | E35: =Clean!E5 -> 1 | F35: =Clean!F5 -> 0 | G35: =Clean!G5 -> 0 | H35: =Clean!H5 -> 2 | I35: =Clean!I5 -> 2 | J35: =Clean!J5 -> 2 | ... AG35: =Clean!AG5 -> 1
A36: บันทึกความดันห้อง (เกณฑ์ 0.08-0.12) (ทุกวันที่บรรจุ) | B36: แผน | C36: =Clean!C6 -> O | D36: =Clean!D6 | E36: =Clean!E6 | F36: =Clean!F6 | G36: =Clean!G6 | H36: =Clean!H6 | I36: =Clean!I6 -> O | J36: =Clean!J6 -> O | ... AG36: =Clean!AG6
B37: ผู้ปฏิบัติ
B38: ผล
A39: บันทึกอุณหภูมิ (เกณฑ์ 18-24 C) (ทุกวันที่บรรจุ) | B39: แผน | C39: =C36 -> O | D39: =D36 | E39: =E36 | F39: =F36 | G39: =G36 | H39: =H36 | I39: =I36 -> O | J39: =J36 -> O | ... AG39: =AG36
B40: ผู้ปฏิบัติ
B41: ผล
A42: บันทึกความชื้นห้อง (เกณฑ์ 40-60%RH) (ทุกวันที่บรรจุ) | B42: แผน | C42: =C39 -> O | D42: =D39 | E42: =E39 | F42: =F39 | G42: =G39 | H42: =H39 | I42: =I39 -> O | J42: =J39 -> O | ... AG42: =AG39
...

Sheet น้ำยา-เครื่อง
B1: น้ำยา | AI1: เครื่อง
B2: =Monitor!C3 -> เดือน กรกฎาคม | AI2: =Monitor!C15 -> เดือน สิงหาคม
B3: =[1]Monthly!C4 -> 1 | C3: =[1]Monthly!D4 -> 2 | D3: =[1]Monthly!E4 -> 3 | E3: =[1]Monthly!F4 -> 4 | F3: =[1]Monthly!G4 -> 5 | G3: =[1]Monthly!H4 -> 6 | H3: =[1]Monthly!I4 -> 7 | I3: =[1]Monthly!J4 -> 8 | ... AE3: =[1]Monthly!AF4 -> 30 | AF3: 31 | AI3: 1 | AJ3: 2 | AK3: 3 | AL3: 4 | AM3: 5 | AN3: 6 | AO3: 7 | AP3: 8 | AQ3: 9 | AR3: 10 | AS3: 11 | AT3: 12 | AU3: 13 | AV3: 14 | AW3: 15 | AX3: 16 | AY3: 17 | AZ3: 18 | BA3: 19 | BB3: 20 | BC3: 21 | BD3: 22 | BE3: 23 | BF3: 24 | BG3: 25 | BH3: 26 | BI3: 27 | BJ3: 28 | BK3: 29 | BL3: 30
A4: น้ำยาฆ่าเชื้อ | B4: 1 | C4: 1 | D4: 1 | G4: 2 | H4: 2 | I4: 2 | J4: 2 | K4: 2 | N4: 1 | O4: 1 | P4: 1 | Q4: 1 | R4: 1 | U4: 2 | V4: 2 | W4: 2 | X4: 2 | Y4: 2 | AB4: 1 | AC4: 1 | AD4: 1 | AE4: 1 | AF4: 1 | AH4: น้ำยาฆ่าเชื้อ | AK4: 2 | AL4: 2 | AM4: 2 | AN4: 2 | AO4: 2 | AR4: 1 | AS4: 1 | AT4: 1 | AU4: 1 | AV4: 1 | AY4: 2 | AZ4: 2 | BA4: 2 | BB4: 2 | BC4: 2 | BF4: 1 | BG4: 1 | BH4: 1 | BI4: 1 | BJ4: 1 | BM4: 2
A5: เครื่อง | B5: 1 | C5: 1 | D5: 1 | E5: 2 | F5: 3 | G5: 1 | H5: 1 | I5: 1 | J5: 1 | K5: 1 | L5: 2 | M5: 3 | N5: 1 | O5: 1 | P5: 1 | Q5: 1 | R5: 1 | S5: 2 | T5: 3 | U5: 1 | V5: 1 | W5: 1 | X5: 1 | Y5: 1 | Z5: 2 | AA5: 3 | AB5: 1 | AC5: 1 | AD5: 1 | AE5: 1 | AF5: 1 | AH5: เครื่อง | AI5: 2 | AJ5: 3 | AK5: 1 | AL5: 1 | AM5: 1 | AN5: 1 | AO5: 1 | AP5: 2 | AQ5: 3 | AR5: 1 | AS5: 1 | AT5: 1 | AU5: 1 | AV5: 1 | AW5: 2 | AX5: 3 | AY5: 1 | AZ5: 1 | BA5: 1 | BB5: 1 | BC5: 1 | BD5: 2 | BE5: 3 | BF5: 1 | BG5: 1 | BH5: 1 | BI5: 1 | BJ5: 1 | BK5: 2 | BL5: 3 | BM5: 1
AH7: แผน | AI7: =AI3 -> 1 | AJ7: =AJ3 -> 2 | AK7: =AK3 -> 3 | AL7: =AL3 -> 4 | AM7: =AM3 -> 5 | AN7: =AN3 -> 6 | AO7: =AO3 -> 7 | AP7: =AP3 -> 8 | ... BJ7: =BJ3 -> 28
A8: แผน D | C8: O | D8: O | E8: O | F8: O | G8: O | J8: O | K8: O | L8: O | M8: O | N8: O | Q8: O | R8: O | S8: O | T8: O | U8: O | X8: O | Y8: O | Z8: O | AA8: O | AB8: O | AE8: O | AF8: O | AH8: แผน D
A9: แผน M
A10: แผน DnD
