Workbook

Sheet MS
A1: แผน/บันทึกการบำรุงรักษาเครื่องมือและห้องสะอาด (สัปดาห์/เดือน/ปี)
A2: ชื่อเครื่องมือ | B2: เครื่องกลั่นน้ำ Stilmas | H2: รหัส | I2: 0725686515050030001 | M2: สถานที่ | O2: ห้องกลั่นน้ำชั้น 6 | T2: ปี | U2: 2568 | W2: ผู้รับผิดชอบ | Z2: Stilmas, UiPS, SP Metrology
A3: รายการ | B3: เดือน | C3: ม.ค. | H3: ก.พ. | L3: มี.ค. | P3: เม.ย. | U3: พ.ค. | Z3: มิ.ย.
A4: (ความถี่) | B4: วันที่ | C4: 1-5 | D4: 6-12 | E4: 13-19 | F4: 20-26 | G4: 27-31 | H4: 1-9 | I4: 10-16 | J4: 17-23 | K4: 24-28 | L4: 1-9 | M4: 10-16 | N4: 17-23 | O4: 24-31 | P4: 1-6 | Q4: 7-13 | R4: 14-20 | S4: 21-27 | T4: 28-30 | U4: 1-4 | V4: 5-11 | W4: 12-18 | X4: 19-25 | Y4: 26-31 | Z4: 1-8 | AA4: 9-15 | AB4: 16-22 | AC4: 23-30
C5: - | D5: - | E5: - | F5: - | G5: - | H5: - | I5: - | J5: - | K5: - | L5: - | M5: - | N5: - | O5: - | P5: - | Q5: - | R5: - | S5: - | T5: - | U5: - | V5: - | W5: - | X5: - | Y5: - | Z5: - | AA5: - | AB5: - | AC5: -
A6: บำรุงรักษา (6 เดือน) | B6: แผน | S6: O
B7: ผู้ปฏิบัติ
B8: วันที่
A9: สอบเทียบอุปกรณ์ (1 ปี) | B9: แผน | S9: 26O
B10: ผู้ปฏิบัติ
B11: วันที่
B12: แผน
B13: ผู้ปฏิบัติ
B14: วันที่
A15: รายการ | B15: เดือน | C15: ก.ค. | H15: ส.ค. | L15: ก.ย. | P15: ต.ค. | U15: พ.ย. | Y15: ธ.ค.
A16: (ความถี่) | B16: วันที่ | C16: 1-6 | D16: 7-13 | E16: 14-20 | F16: 21-27 | G16: 28-31 | H16: 1-10 | I16: 11-17 | J16: 18-24 | K16: 25-31 | L16: 1-7 | M16: 8-14 | N16: 15-21 | O16: 22-30 | P16: 1-5 | Q16: 6-12 | R16: 13-19 | S16: 20-26 | T16: 27-31 | U16: 1-9 | V16: 10-16 | W16: 17-23 | X16: 24-30 | Y16: 1-7 | Z16: 8-14 | AA16: 15-21 | AB16: 22-28 | AC16: 29-31
C17: - | D17: - | E17: - | F17: - | G17: - | H17: - | I17: - | J17: - | K17: - | L17: - | M17: - | N17: - | O17: - | P17: - | Q17: - | R17: - | S17: - | T17: - | U17: - | V17: - | W17: - | X17: - | Y17: - | Z17: - | AA17: - | AB17: - | AC17: -
A18: บำรุงรักษา (6 เดือน) | B18: แผน | S18: O
B19: ผู้ปฏิบัติ
B20: วันที่
A21: สอบเทียบอุปกรณ์ (1 ปี) | B21: แผน
B22: ผู้ปฏิบัติ
B23: วันที่
B24: แผน
B25: ผู้ปฏิบัติ
B26: วันที่
A27: หมายเหตุ วงกลม (O) หมายถึง สัปดาห์ที่ต้องทำการบำรุงรักษาเครื่องมือหรือห้องสะอาด เมื่อดำเนินการตามแผนแล้ว ให้ทำเครื่องหมายถูก (/) ในวงกลมที่ระบุ
P29: จัดทำโดย | R29: พีรวัส | U29: อนุมัติโดย | W29: วรพงศ์ | Z29: วันที่ | AA29: 45748
A30: แผน/บันทึกการบำรุงรักษาเครื่องมือและห้องสะอาด (สัปดาห์/เดือน/ปี)
A31: ชื่อเครื่องมือ | B31: เครื่องกลั่นน้ำ Stilmas | H31: รหัส | I31: 0725686515050030001 | M31: สถานที่ | O31: ห้องกลั่นน้ำชั้น 6 | T31: ปี | U31: 2569 | W31: ผู้รับผิดชอบ | Z31: UiPS, SP Metrology
A32: รายการ | B32: เดือน | C32: ม.ค. | H32: ก.พ. | L32: มี.ค. | P32: เม.ย. | U32: พ.ค. | Z32: มิ.ย.
A33: (ความถี่) | B33: วันที่ | C33: 1-4 | D33: 5-11 | E33: 12-18 | F33: 19-25 | G33: 26-31 | H33: 1-7 | I33: 9-15 | J33: 16-22 | K33: 23-28 | L33: 1-8 | M33: 9-15 | N33: 16-22 | O33: 23-31 | P33: 1-5 | Q33: 6-12 | R33: 13-19 | S33: 20-26 | T33: 27-30 | U33: 1-3 | V33: 4-10 | W33: 11-17 | X33: 18-24 | Y33: 25-31 | Z33: 1-7 | AA33: 8-14 | AB33: 15-21 | AC33: 22-30
C34: - | D34: - | E34: - | F34: - | G34: - | H34: - | I34: - | J34: - | K34: - | L34: - | M34: - | N34: - | O34: - | P34: - | Q34: - | R34: - | S34: - | T34: - | U34: - | V34: - | W34: - | X34: - | Y34: - | Z34: - | AA34: - | AB34: - | AC34: -
A35: บำรุงรักษา (6 เดือน) | B35: แผน | S35: O
B36: ผู้ปฏิบัติ
B37: วันที่
A38: สอบเทียบอุปกรณ์ (1 ปี) | B38: แผน | S38: O
B39: ผู้ปฏิบัติ
B40: วันที่
B41: แผน
...

Sheet Yearly
A1: แผน/บันทึกการบำรุงรักษาเครื่องมือและห้องสะอาด (สัปดาห์/เดือน/ปี)
A2: ชื่อเครื่องมือ | B2: เครื่องพิมพ์-ตัดสายอัตโนมัติ 268. 1 | H2: รหัส | I2: SUP 44-6515-127-1 | M2: สถานที่ | O2: ห้องพิมพ์-ตัดสาย | T2: ปี | U2: 2569 | W2: ผู้รับผิดชอบ | Z2: ชาดินีย์
A3: รายการ | B3: เดือน | C3: ม.ค. | H3: ก.พ. | L3: มี.ค. | P3: เม.ย. | U3: พ.ค. | Z3: มิ.ย.
A4: (ความถี่) | B4: วันที่ | C4: 1-5 | D4: 6-12 | E4: 13-19 | F4: 20-26 | G4: 27-31 | H4: 1-9 | I4: 10-16 | J4: 17-23 | K4: 24-28 | L4: 1-9 | M4: 10-16 | N4: 17-23 | O4: 24-31 | P4: 1-6 | Q4: 7-13 | R4: 14-20 | S4: 21-27 | T4: 28-30 | U4: 1-4 | V4: 5-11 | W4: 12-18 | X4: 19-25 | Y4: 26-31 | Z4: 1-8 | AA4: 9-15 | AB4: 16-22 | AC4: 23-30
B5: น้ำยาฆ่าเชื้อ | C5: - | D5: - | E5: - | F5: - | G5: - | H5: - | I5: - | J5: - | K5: - | L5: - | M5: - | N5: - | O5: - | P5: - | Q5: - | R5: - | S5: - | T5: - | U5: - | V5: - | W5: - | X5: - | Y5: - | Z5: - | AA5: - | AB5: - | AC5: -
A6: ล้างทำความสะอาดชุดแม่พิมพ์ตัวเลข (1 ปี) | B6: แผน | X6: O
B7: ผู้ปฏิบัติ
B8: วันที่
A9: เปลี่ยนแบตเตอรี่ (1 ปี) | B9: แผน
B10: ผู้ปฏิบัติ
B11: วันที่
A12: หยอดน้ำมัน WD40 และจาระบี (1 เดือน) | B12: แผน
B13: ผู้ปฏิบัติ
B14: วันที่
A15: รายการ | B15: เดือน | C15: ก.ค. | H15: ส.ค. | L15: ก.ย. | P15: ต.ค. | U15: พ.ย. | Y15: ธ.ค.
A16: (ความถี่) | B16: วันที่ | C16: 1-6 | D16: 7-13 | E16: 14-20 | F16: 21-27 | G16: 28-31 | H16: 1-10 | I16: 11-17 | J16: 18-24 | K16: 25-31 | L16: 1-7 | M16: 8-14 | N16: 15-21 | O16: 22-30 | P16: 1-5 | Q16: 6-12 | R16: 13-19 | S16: 20-26 | T16: 27-31 | U16: 1-9 | V16: 10-16 | W16: 17-23 | X16: 24-30 | Y16: 1-7 | Z16: 8-14 | AA16: 15-21 | AB16: 22-28 | AC16: 29-31
B17: น้ำยาฆ่าเชื้อ | C17: - | D17: - | E17: - | F17: - | G17: - | H17: - | I17: - | J17: - | K17: - | L17: - | M17: - | N17: - | O17: - | P17: - | Q17: - | R17: - | S17: - | T17: - | U17: - | V17: - | W17: - | X17: - | Y17: - | Z17: - | AA17: - | AB17: - | AC17: -
A18: ล้างทำความสะอาดชุดแม่พิมพ์ตัวเลข (1 ปี) | B18: แผน
B19: ผู้ปฏิบัติ
B20: วันที่
A21: เปลี่ยนแบตเตอรี่ (1 ปี) | B21: แผน | C21: O
B22: ผู้ปฏิบัติ
B23: วันที่
A24: หยอดน้ำมัน WD40 และจาระบี (1 เดือน) | B24: แผน
B25: ผู้ปฏิบัติ
B26: วันที่
A27: หมายเหตุ วงกลม (O) หมายถึง สัปดาห์ที่ต้องทำการบำรุงรักษาเครื่องมือหรือห้องสะอาด เมื่อดำเนินการตามแผนแล้ว ให้ทำเครื่องหมายถูก (/) ในวงกลมที่ระบุ | W27: น้ำยาฆ่าเชื้อ (1) Chlorhex-C (2) Benz Cl
A28: เปลี่ยนแบตเตอรี่ (1 ปี) ครั้งล่าสุด 1/7/2568 ใช้แบต Mitsubishi 3.6V และตอนเปลี่ยนแบตให้เปิดเครื่องไว้
P29: จัดทำโดย | R29: พีรวัส | U29: อนุมัติโดย | W29: วรพงศ์ | Z29: วันที่ | AA29: 46021
A31: แผน/บันทึกการบำรุงรักษาเครื่องมือและห้องสะอาด (สัปดาห์/เดือน/ปี)
A32: ชื่อเครื่องมือ | B32: เครื่องพิมพ์-ตัดสายอัตโนมัติ 268. 2 | H32: รหัส | I32: SUP 44-6515-127-2 | M32: สถานที่ | O32: ห้องพิมพ์-ตัดสาย | T32: ปี | U32: =$U$2 -> 2569 | W32: ผู้รับผิดชอบ | Z32: ชาดินีย์
A33: รายการ | B33: เดือน | C33: ม.ค. | H33: ก.พ. | L33: มี.ค. | P33: เม.ย. | U33: พ.ค. | Z33: มิ.ย.
A34: (ความถี่) | B34: วันที่ | C34: =C4 -> 1-5 | D34: =D4 -> 6-12 | E34: =E4 -> 13-19 | F34: =F4 -> 20-26 | G34: =G4 -> 27-31 | H34: =H4 -> 1-9 | I34: =I4 -> 10-16 | J34: =J4 -> 17-23 | ... AC34: =AC4 -> 23-30
B35: น้ำยาฆ่าเชื้อ | C35: - | D35: - | E35: - | F35: - | G35: - | H35: - | I35: - | J35: - | K35: - | L35: - | M35: - | N35: - | O35: - | P35: - | Q35: - | R35: - | S35: - | T35: - | U35: - | V35: - | W35: - | X35: - | Y35: - | Z35: - | AA35: - | AB35: - | AC35: -
A36: ล้างทำความสะอาดชุดแม่พิมพ์ตัวเลข (1 ปี) | B36: แผน | X36: O
B37: ผู้ปฏิบัติ
B38: วันที่
A39: เปลี่ยนแบตเตอรี่ (1 ปี) | B39: แผน | H39: O
B40: ผู้ปฏิบัติ
B41: วันที่
...

Sheet Monthly
A1: แผน/บันทึกการบำรุงรักษาเครื่องมือและห้องสะอาด (วัน)
A2: ชื่อเครื่องมือ | B2: เครื่องพิมพ์-ตัดสายอัตโนมัติ 268. 1 | H2: รหัส | I2: SUP 44-6515-127-1 | M2: สถานที่ | O2: ห้องพิมพ์-ตัดสาย | T2: ปี | U2: 2569 | W2: ผู้รับผิดชอบ | Z2: ชาดินีย์
A3: รายการ | B3: เดือน | C3: เดือน กรกฏาคม
A4: (ความถี่) | B4: วันที่ | C4: 1 | D4: 2 | E4: 3 | F4: 4 | G4: 5 | H4: 6 | I4: 7 | J4: 8 | K4: 9 | L4: 10 | M4: 11 | N4: 12 | O4: 13 | P4: 14 | Q4: 15 | R4: 16 | S4: 17 | T4: 18 | U4: 19 | V4: 20 | W4: 21 | X4: 22 | Y4: 23 | Z4: 24 | AA4: 25 | AB4: 26 | AC4: 27 | AD4: 28 | AE4: 29 | AF4: 30 | AG4: 31
B5: น้ำยาฆ่าเชื้อ | C5: =_xlfn.IFNA(IF(OR(C4="",C4=0),"",(VLOOKUP(B5,'น้ำยา-เครื่อง'!$A:$AF,C4+1,FALSE))),"") -> 1 | D5: =_xlfn.IFNA(IF(OR(D4="",D4=0),"",(VLOOKUP(B5,'น้ำยา-เครื่อง'!$A:$AF,D4+1,FALSE))),"") -> 1 | E5: =_xlfn.IFNA(IF(OR(E4="",E4=0),"",(VLOOKUP(B5,'น้ำยา-เครื่อง'!$A:$AF,E4+1,FALSE))),"") -> 1 | F5: =_xlfn.IFNA(IF(OR(F4="",F4=0),"",(VLOOKUP(B5,'น้ำยา-เครื่อง'!$A:$AF,F4+1,FALSE))),"") -> 0 | G5: =_xlfn.IFNA(IF(OR(G4="",G4=0),"",(VLOOKUP(B5,'น้ำยา-เครื่อง'!$A:$AF,G4+1,FALSE))),"") -> 0 | H5: =_xlfn.IFNA(IF(OR(H4="",H4=0),"",(VLOOKUP(B5,'น้ำยา-เครื่อง'!$A:$AF,H4+1,FALSE))),"") -> 2 | I5: =_xlfn.IFNA(IF(OR(I4="",I4=0),"",(VLOOKUP(B5,'น้ำยา-เครื่อง'!$A:$AF,I4+1,FALSE))),"") -> 2 | J5: =_xlfn.IFNA(IF(OR(J4="",J4=0),"",(VLOOKUP(B5,'น้ำยา-เครื่อง'!$A:$AF,J4+1,FALSE))),"") -> 2 | K5: =_xlfn.IFNA(IF(OR(K4="",K4=0),"",(VLOOKUP(B5,'น้ำยา-เครื่อง'!$A:$AF,K4+1,FALSE))),"") -> 2 | L5: =_xlfn.IFNA(IF(OR(L4="",L4=0),"",(VLOOKUP(B5,'น้ำยา-เครื่อง'!$A:$AF,L4+1,FALSE))),"") -> 2 | M5: =_xlfn.IFNA(IF(OR(M4="",M4=0),"",(VLOOKUP(B5,'น้ำยา-เครื่อง'!$A:$AF,M4+1,FALSE))),"") -> 0 | N5: =_xlfn.IFNA(IF(OR(N4="",N4=0),"",(VLOOKUP(B5,'น้ำยา-เครื่อง'!$A:$AF,N4+1,FALSE))),"") -> 0 | O5: =_xlfn.IFNA(IF(OR(O4="",O4=0),"",(VLOOKUP(B5,'น้ำยา-เครื่อง'!$A:$AF,O4+1,FALSE))),"") -> 1 | P5: =_xlfn.IFNA(IF(OR(P4="",P4=0),"",(VLOOKUP(B5,'น้ำยา-เครื่อง'!$A:$AF,P4+1,FALSE))),"") -> 1 | Q5: =_xlfn.IFNA(IF(OR(Q4="",Q4=0),"",(VLOOKUP(B5,'น้ำยา-เครื่อง'!$A:$AF,Q4+1,FALSE))),"") -> 1 | R5: =_xlfn.IFNA(IF(OR(R4="",R4=0),"",(VLOOKUP(B5,'น้ำยา-เครื่อง'!$A:$AF,R4+1,FALSE))),"") -> 1 | S5: =_xlfn.IFNA(IF(OR(S4="",S4=0),"",(VLOOKUP(B5,'น้ำยา-เครื่อง'!$A:$AF,S4+1,FALSE))),"") -> 1 | T5: =_xlfn.IFNA(IF(OR(T4="",T4=0),"",(VLOOKUP(B5,'น้ำยา-เครื่อง'!$A:$AF,T4+1,FALSE))),"") -> 0 | U5: =_xlfn.IFNA(IF(OR(U4="",U4=0),"",(VLOOKUP(B5,'น้ำยา-เครื่อง'!$A:$AF,U4+1,FALSE))),"") -> 0 | V5: =_xlfn.IFNA(IF(OR(V4="",V4=0),"",(VLOOKUP(B5,'น้ำยา-เครื่อง'!$A:$AF,V4+1,FALSE))),"") -> 2 | W5: =_xlfn.IFNA(IF(OR(W4="",W4=0),"",(VLOOKUP(B5,'น้ำยา-เครื่อง'!$A:$AF,W4+1,FALSE))),"") -> 2 | X5: =_xlfn.IFNA(IF(OR(X4="",X4=0),"",(VLOOKUP(B5,'น้ำยา-เครื่อง'!$A:$AF,X4+1,FALSE))),"") -> 2 | Y5: =_xlfn.IFNA(IF(OR(Y4="",Y4=0),"",(VLOOKUP(B5,'น้ำยา-เครื่อง'!$A:$AF,Y4+1,FALSE))),"") -> 2 | Z5: =_xlfn.IFNA(IF(OR(Z4="",Z4=0),"",(VLOOKUP(B5,'น้ำยา-เครื่อง'!$A:$AF,Z4+1,FALSE))),"") -> 2 | AA5: =_xlfn.IFNA(IF(OR(AA4="",AA4=0),"",(VLOOKUP(B5,'น้ำยา-เครื่อง'!$A:$AF,AA4+1,FALSE))),"") -> 0 | AB5: =_xlfn.IFNA(IF(OR(AB4="",AB4=0),"",(VLOOKUP(B5,'น้ำยา-เครื่อง'!$A:$AF,AB4+1,FALSE))),"") -> 0 | AC5: =_xlfn.IFNA(IF(OR(AC4="",AC4=0),"",(VLOOKUP(B5,'น้ำยา-เครื่อง'!$A:$AF,AC4+1,FALSE))),"") -> 1 | AD5: =_xlfn.IFNA(IF(OR(AD4="",AD4=0),"",(VLOOKUP(B5,'น้ำยา-เครื่อง'!$A:$AF,AD4+1,FALSE))),"") -> 1 | AE5: =_xlfn.IFNA(IF(OR(AE4="",AE4=0),"",(VLOOKUP(B5,'น้ำยา-เครื่อง'!$A:$AF,AE4+1,FALSE))),"") -> 1 | AF5: =_xlfn.IFNA(IF(OR(AF4="",AF4=0),"",(VLOOKUP(B5,'น้ำยา-เครื่อง'!$A:$AF,AF4+1,FALSE))),"") -> 1 | AG5: =_xlfn.IFNA(IF(OR(AG4="",AG4=0),"",(VLOOKUP(B5,'น้ำยา-เครื่อง'!$A:$AF,AG4+1,FALSE))),"") -> 1
A6: เช็ดทำความสะอาดเครื่องด้วย Alcohol 95 % (วันที่ใช้งาน) | B6: แผน
B7: ผู้ปฏิบัติ
B9: แผน
B10: ผู้ปฏิบัติ
B12: แผน
B13: ผู้ปฏิบัติ
A15: รายการ | B15: เดือน | C15: เดือน สิงหาคม
A16: (ความถี่) | B16: วันที่ | C16: 1 | D16: 2 | E16: 3 | F16: 4 | G16: 5 | H16: 6 | I16: 7 | J16: 8 | K16: 9 | L16: 10 | M16: 11 | N16: 12 | O16: 13 | P16: 14 | Q16: 15 | R16: 16 | S16: 17 | T16: 18 | U16: 19 | V16: 20 | W16: 21 | X16: 22 | Y16: 23 | Z16: 24 | AA16: 25 | AB16: 26 | AC16: 27 | AD16: 28 | AE16: 29 | AF16: 30
B17: น้ำยาฆ่าเชื้อ | C17: =_xlfn.IFNA(IF(OR(C16="",C16=0),"",(VLOOKUP($B17,'น้ำยา-เครื่อง'!$A$14:$AF$23,C16+1,FALSE))),"") -> 0 | D17: =_xlfn.IFNA(IF(OR(D16="",D16=0),"",(VLOOKUP($B17,'น้ำยา-เครื่อง'!$A$14:$AF$23,D16+1,FALSE))),"") -> 0 | E17: =_xlfn.IFNA(IF(OR(E16="",E16=0),"",(VLOOKUP($B17,'น้ำยา-เครื่อง'!$A$14:$AF$23,E16+1,FALSE))),"") -> 2 | F17: =_xlfn.IFNA(IF(OR(F16="",F16=0),"",(VLOOKUP($B17,'น้ำยา-เครื่อง'!$A$14:$AF$23,F16+1,FALSE))),"") -> 2 | G17: =_xlfn.IFNA(IF(OR(G16="",G16=0),"",(VLOOKUP($B17,'น้ำยา-เครื่อง'!$A$14:$AF$23,G16+1,FALSE))),"") -> 2 | H17: =_xlfn.IFNA(IF(OR(H16="",H16=0),"",(VLOOKUP($B17,'น้ำยา-เครื่อง'!$A$14:$AF$23,H16+1,FALSE))),"") -> 2 | I17: =_xlfn.IFNA(IF(OR(I16="",I16=0),"",(VLOOKUP($B17,'น้ำยา-เครื่อง'!$A$14:$AF$23,I16+1,FALSE))),"") -> 2 | J17: =_xlfn.IFNA(IF(OR(J16="",J16=0),"",(VLOOKUP($B17,'น้ำยา-เครื่อง'!$A$14:$AF$23,J16+1,FALSE))),"") -> 0 | ... AG17: =_xlfn.IFNA(IF(OR(AG16="",AG16=0),"",(VLOOKUP($B17,'น้ำยา-เครื่อง'!$A$14:$AF$23,AG16+1,FALSE))),"")
A18: เช็ดทำความสะอาดเครื่องด้วย Alcohol 95 % (วันที่ใช้งาน) | B18: แผน
B19: ผู้ปฏิบัติ
B21: แผน
B22: ผู้ปฏิบัติ
B24: แผน
B25: ผู้ปฏิบัติ
A27: หมายเหตุ วงกลม (O) หมายถึง สัปดาห์ที่ต้องทำการบำรุงรักษาเครื่องมือหรือห้องสะอาด เมื่อดำเนินการตามแผนแล้ว ให้ทำเครื่องหมายถูก (/) ในวงกลมที่ระบุ | W27: น้ำยาฆ่าเชื้อ (1) Chlorhex - C (2) Benz Cl
P29: จัดทำโดย | R29: พีรวัส | U29: อนุมัติโดย | W29: วรพงศ์ | Z29: วันที่ | AA29: 46204
A31: แผน/บันทึกการบำรุงรักษาเครื่องมือและห้องสะอาด (วัน)
A32: ชื่อเครื่องมือ | B32: เครื่องพิมพ์-ตัดสายอัตโนมัติ 268. 2 | H32: รหัส | I32: SUP 44-6515-127-2 | M32: สถานที่ | O32: ห้องพิมพ์-ตัดสาย | T32: ปี | U32: =$U$2 -> 2569 | W32: ผู้รับผิดชอบ | Z32: ชาดินีย์
A33: รายการ | B33: เดือน | C33: =C3 -> เดือน กรกฏาคม
A34: (ความถี่) | B34: วันที่ | C34: =C4 -> 1 | D34: =D4 -> 2 | E34: =E4 -> 3 | F34: =F4 -> 4 | G34: =G4 -> 5 | H34: =H4 -> 6 | I34: =I4 -> 7 | J34: =J4 -> 8 | ... AG34: =AG4 -> 31
B35: น้ำยาฆ่าเชื้อ | C35: =_xlfn.IFNA(IF(OR(C34="",C34=0),"",(VLOOKUP(B35,'น้ำยา-เครื่อง'!$A:$AF,C34+1,FALSE))),"") -> 1 | D35: =_xlfn.IFNA(IF(OR(D34="",D34=0),"",(VLOOKUP(B35,'น้ำยา-เครื่อง'!$A:$AF,D34+1,FALSE))),"") -> 1 | E35: =_xlfn.IFNA(IF(OR(E34="",E34=0),"",(VLOOKUP(B35,'น้ำยา-เครื่อง'!$A:$AF,E34+1,FALSE))),"") -> 1 | F35: =_xlfn.IFNA(IF(OR(F34="",F34=0),"",(VLOOKUP(B35,'น้ำยา-เครื่อง'!$A:$AF,F34+1,FALSE))),"") -> 0 | G35: =_xlfn.IFNA(IF(OR(G34="",G34=0),"",(VLOOKUP(B35,'น้ำยา-เครื่อง'!$A:$AF,G34+1,FALSE))),"") -> 0 | H35: =_xlfn.IFNA(IF(OR(H34="",H34=0),"",(VLOOKUP(B35,'น้ำยา-เครื่อง'!$A:$AF,H34+1,FALSE))),"") -> 2 | I35: =_xlfn.IFNA(IF(OR(I34="",I34=0),"",(VLOOKUP(B35,'น้ำยา-เครื่อง'!$A:$AF,I34+1,FALSE))),"") -> 2 | J35: =_xlfn.IFNA(IF(OR(J34="",J34=0),"",(VLOOKUP(B35,'น้ำยา-เครื่อง'!$A:$AF,J34+1,FALSE))),"") -> 2 | K35: =_xlfn.IFNA(IF(OR(K34="",K34=0),"",(VLOOKUP(B35,'น้ำยา-เครื่อง'!$A:$AF,K34+1,FALSE))),"") -> 2 | L35: =_xlfn.IFNA(IF(OR(L34="",L34=0),"",(VLOOKUP(B35,'น้ำยา-เครื่อง'!$A:$AF,L34+1,FALSE))),"") -> 2 | M35: =_xlfn.IFNA(IF(OR(M34="",M34=0),"",(VLOOKUP(B35,'น้ำยา-เครื่อง'!$A:$AF,M34+1,FALSE))),"") -> 0 | N35: =_xlfn.IFNA(IF(OR(N34="",N34=0),"",(VLOOKUP(B35,'น้ำยา-เครื่อง'!$A:$AF,N34+1,FALSE))),"") -> 0 | O35: =_xlfn.IFNA(IF(OR(O34="",O34=0),"",(VLOOKUP(B35,'น้ำยา-เครื่อง'!$A:$AF,O34+1,FALSE))),"") -> 1 | P35: =_xlfn.IFNA(IF(OR(P34="",P34=0),"",(VLOOKUP(B35,'น้ำยา-เครื่อง'!$A:$AF,P34+1,FALSE))),"") -> 1 | Q35: =_xlfn.IFNA(IF(OR(Q34="",Q34=0),"",(VLOOKUP(B35,'น้ำยา-เครื่อง'!$A:$AF,Q34+1,FALSE))),"") -> 1 | R35: =_xlfn.IFNA(IF(OR(R34="",R34=0),"",(VLOOKUP(B35,'น้ำยา-เครื่อง'!$A:$AF,R34+1,FALSE))),"") -> 1 | S35: =_xlfn.IFNA(IF(OR(S34="",S34=0),"",(VLOOKUP(B35,'น้ำยา-เครื่อง'!$A:$AF,S34+1,FALSE))),"") -> 1 | T35: =_xlfn.IFNA(IF(OR(T34="",T34=0),"",(VLOOKUP(B35,'น้ำยา-เครื่อง'!$A:$AF,T34+1,FALSE))),"") -> 0 | U35: =_xlfn.IFNA(IF(OR(U34="",U34=0),"",(VLOOKUP(B35,'น้ำยา-เครื่อง'!$A:$AF,U34+1,FALSE))),"") -> 0 | V35: =_xlfn.IFNA(IF(OR(V34="",V34=0),"",(VLOOKUP(B35,'น้ำยา-เครื่อง'!$A:$AF,V34+1,FALSE))),"") -> 2 | W35: =_xlfn.IFNA(IF(OR(W34="",W34=0),"",(VLOOKUP(B35,'น้ำยา-เครื่อง'!$A:$AF,W34+1,FALSE))),"") -> 2 | X35: =_xlfn.IFNA(IF(OR(X34="",X34=0),"",(VLOOKUP(B35,'น้ำยา-เครื่อง'!$A:$AF,X34+1,FALSE))),"") -> 2 | Y35: =_xlfn.IFNA(IF(OR(Y34="",Y34=0),"",(VLOOKUP(B35,'น้ำยา-เครื่อง'!$A:$AF,Y34+1,FALSE))),"") -> 2 | Z35: =_xlfn.IFNA(IF(OR(Z34="",Z34=0),"",(VLOOKUP(B35,'น้ำยา-เครื่อง'!$A:$AF,Z34+1,FALSE))),"") -> 2 | AA35: =_xlfn.IFNA(IF(OR(AA34="",AA34=0),"",(VLOOKUP(B35,'น้ำยา-เครื่อง'!$A:$AF,AA34+1,FALSE))),"") -> 0 | AB35: =_xlfn.IFNA(IF(OR(AB34="",AB34=0),"",(VLOOKUP(B35,'น้ำยา-เครื่อง'!$A:$AF,AB34+1,FALSE))),"") -> 0 | AC35: =_xlfn.IFNA(IF(OR(AC34="",AC34=0),"",(VLOOKUP(B35,'น้ำยา-เครื่อง'!$A:$AF,AC34+1,FALSE))),"") -> 1 | AD35: =_xlfn.IFNA(IF(OR(AD34="",AD34=0),"",(VLOOKUP(B35,'น้ำยา-เครื่อง'!$A:$AF,AD34+1,FALSE))),"") -> 1 | AE35: =_xlfn.IFNA(IF(OR(AE34="",AE34=0),"",(VLOOKUP(B35,'น้ำยา-เครื่อง'!$A:$AF,AE34+1,FALSE))),"") -> 1 | AF35: =_xlfn.IFNA(IF(OR(AF34="",AF34=0),"",(VLOOKUP(B35,'น้ำยา-เครื่อง'!$A:$AF,AF34+1,FALSE))),"") -> 1 | AG35: =_xlfn.IFNA(IF(OR(AG34="",AG34=0),"",(VLOOKUP(B35,'น้ำยา-เครื่อง'!$A:$AF,AG34+1,FALSE))),"") -> 1
A36: เช็ดทำความสะอาดเครื่องด้วย Alcohol 95 % (วันที่ใช้งาน) | B36: แผน
B37: ผู้ปฏิบัติ
A39: หยอดน้ำมัน WD40 (3 วัน) | B39: แผน
B40: ผู้ปฏิบัติ
A42: หยอดน้ำมันจารบี (1 สัปดาห์) | B42: แผน
B43: ผู้ปฏิบัติ
A45: รายการ | B45: เดือน | C45: =C15 -> เดือน สิงหาคม
A46: (ความถี่) | B46: วันที่ | C46: =C16 -> 1 | D46: =D16 -> 2 | E46: =E16 -> 3 | F46: =F16 -> 4 | G46: =G16 -> 5 | H46: =H16 -> 6 | I46: =I16 -> 7 | J46: =J16 -> 8 | ... AG46: =AG16 -> 0
B47: น้ำยาฆ่าเชื้อ | C47: =_xlfn.IFNA(IF(OR(C46="",C46=0),"",(VLOOKUP($B47,'น้ำยา-เครื่อง'!$A$14:$AF$23,C46+1,FALSE))),"") -> 0 | D47: =_xlfn.IFNA(IF(OR(D46="",D46=0),"",(VLOOKUP($B47,'น้ำยา-เครื่อง'!$A$14:$AF$23,D46+1,FALSE))),"") -> 0 | E47: =_xlfn.IFNA(IF(OR(E46="",E46=0),"",(VLOOKUP($B47,'น้ำยา-เครื่อง'!$A$14:$AF$23,E46+1,FALSE))),"") -> 2 | F47: =_xlfn.IFNA(IF(OR(F46="",F46=0),"",(VLOOKUP($B47,'น้ำยา-เครื่อง'!$A$14:$AF$23,F46+1,FALSE))),"") -> 2 | G47: =_xlfn.IFNA(IF(OR(G46="",G46=0),"",(VLOOKUP($B47,'น้ำยา-เครื่อง'!$A$14:$AF$23,G46+1,FALSE))),"") -> 2 | H47: =_xlfn.IFNA(IF(OR(H46="",H46=0),"",(VLOOKUP($B47,'น้ำยา-เครื่อง'!$A$14:$AF$23,H46+1,FALSE))),"") -> 2 | I47: =_xlfn.IFNA(IF(OR(I46="",I46=0),"",(VLOOKUP($B47,'น้ำยา-เครื่อง'!$A$14:$AF$23,I46+1,FALSE))),"") -> 2 | J47: =_xlfn.IFNA(IF(OR(J46="",J46=0),"",(VLOOKUP($B47,'น้ำยา-เครื่อง'!$A$14:$AF$23,J46+1,FALSE))),"") -> 0 | ... AG47: =_xlfn.IFNA(IF(OR(AG46="",AG46=0),"",(VLOOKUP($B47,'น้ำยา-เครื่อง'!$A$14:$AF$23,AG46+1,FALSE))),"")
A48: เช็ดทำความสะอาดเครื่องด้วย Alcohol 95 % (วันที่ใช้งาน) | B48: แผน
B49: ผู้ปฏิบัติ
A51: หยอดน้ำมัน WD40 (3 วัน) | B51: แผน
B52: ผู้ปฏิบัติ
...

Sheet น้ำยา-เครื่อง
B1: น้ำยา
B2: =Monthly!C3 -> เดือน กรกฏาคม
B3: =Monthly!C4 -> 1 | C3: =Monthly!D4 -> 2 | D3: =Monthly!E4 -> 3 | E3: =Monthly!F4 -> 4 | F3: =Monthly!G4 -> 5 | G3: =Monthly!H4 -> 6 | H3: =Monthly!I4 -> 7 | I3: =Monthly!J4 -> 8 | ... AE3: =Monthly!AF4 -> 30 | AF3: 31
A4: น้ำยาฆ่าเชื้อ | B4: 1 | C4: 1 | D4: 1 | G4: 2 | H4: 2 | I4: 2 | J4: 2 | K4: 2 | N4: 1 | O4: 1 | P4: 1 | Q4: 1 | R4: 1 | U4: 2 | V4: 2 | W4: 2 | X4: 2 | Y4: 2 | AB4: 1 | AC4: 1 | AD4: 1 | AE4: 1 | AF4: 1
A5: เครื่อง | B5: 1 | C5: 1 | D5: 1 | E5: 2 | F5: 3 | G5: 1 | H5: 1 | I5: 1 | J5: 1 | K5: 1 | L5: 2 | M5: 3 | N5: 1 | O5: 1 | P5: 1 | Q5: 1 | R5: 1 | S5: 2 | T5: 3 | U5: 1 | V5: 1 | W5: 1 | X5: 1 | Y5: 1 | Z5: 2 | AA5: 3 | AB5: 1 | AC5: 1 | AD5: 1 | AE5: 1 | AF5: 1
A8: แผน D | C8: O | D8: O | E8: O | F8: O | G8: O | J8: O | K8: O | L8: O | M8: O | N8: O | Q8: O | R8: O | S8: O | T8: O | U8: O | X8: O | Y8: O | Z8: O | AA8: O | AB8: O | AE8: O
A9: แผน M
A10: แผน DnD
B15: เครื่อง
B16: =Monthly!C15 -> เดือน สิงหาคม
B17: =Monthly!C16 -> 1 | C17: =Monthly!D16 -> 2 | D17: =Monthly!E16 -> 3 | E17: =Monthly!F16 -> 4 | F17: =Monthly!G16 -> 5 | G17: =Monthly!H16 -> 6 | H17: =Monthly!I16 -> 7 | I17: =Monthly!J16 -> 8 | ... AC17: =Monthly!AD16 -> 28 | AD17: 29 | AE17: 30 | AF17: 31
A18: น้ำยาฆ่าเชื้อ | D18: 2 | E18: 2 | F18: 2 | G18: 2 | H18: 2 | K18: 1 | L18: 1 | M18: 1 | N18: 1 | O18: 1 | R18: 2 | S18: 2 | T18: 2 | U18: 2 | V18: 2 | Y18: 1 | Z18: 1 | AA18: 1 | AB18: 1 | AC18: 1 | AF18: 2
A19: เครื่อง | B19: 2 | C19: 3 | D19: 1 | E19: 1 | F19: 1 | G19: 1 | H19: 1 | I19: 2 | J19: 3 | K19: 1 | L19: 1 | M19: 1 | N19: 1 | O19: 1 | P19: 2 | Q19: 3 | R19: 1 | S19: 1 | T19: 1 | U19: 1 | V19: 1 | W19: 2 | X19: 3 | Y19: 1 | Z19: 1 | AA19: 1 | AB19: 1 | AC19: 1 | AD19: 2 | AE19: 3 | AF19: 1
A21: แผน | B21: =B17 -> 1 | C21: =C17 -> 2 | D21: =D17 -> 3 | E21: =E17 -> 4 | F21: =F17 -> 5 | G21: =G17 -> 6 | H21: =H17 -> 7 | I21: =I17 -> 8 | ... AF21: =AF17 -> 31
A22: แผน D

Sheet List Cleanroom
A1: รายการบำรุงรักษา | B1: Cleanroom
A2: ชื่อเครื่องมือ | B2: ห้อง Cleanroom | H2: รหัส | I2: BR 1 – BR 51 | M2: สถานที่ | O2: ห้องสะอาด | T2: ปี | U2: 2566 | W2: ผู้รับผิดชอบ | Z2: Global tech, ประเสริฐพงษ์
A4: ราย | B4: ความถี่ | C4: หน่วย
A7: - ทำความสะอาดด้านบนเพดานคลีนรูมและ cat walk | B7: 6 | C7: เดือน
A8: - บำรุงรักษา AHU และตู้ควบคุมไฟฟ้าโดยบริษัท | B8: 3 | C8: เดือน
A9: - บำรุงรักษา air shower, pass box โดยบริษัท | B9: 3 | C9: เดือน
A10: - เปลี่ยน prefilter | B10: 6 | C10: เดือน
A11: - เปลี่ยนลูกปืนมอเตอร์ | B11: 5 | C11: ปี

Sheet List T1
A1: รายการบำรุงรักษา | B1: Cleanroom
A2: ชื่อเครื่องมือ | B2: เครื่อง Thermoforming machine | H2: รหัส | I2: 0725606530021150002 | M2: สถานที่ | O2: ห้องแพคกิ้ง | T2: ปี | U2: 2566 | W2: ผู้รับผิดชอบ | Z2: บ.Goodtime , ประเสริฐพงษ์
A4: ราย | B4: ความถี่ | C4: หน่วย
A7: หัวข้อการบำรุงรักษาโดยบริษัททุก 3 เดือน | B7: 3 | C7: เดือน
A8: 1.ตรวจเช็คอุปกรณ์ safety valve
A9: 2.ทำความสะอาดตัวกรอง ท่อทางเดินไอน้ำ (Strainer)
A10: 3.ตรวจเช็คและถอดล้าง Stream trap ทุกตัว
A11: 4.ตรวจเช็ครอยรั่วตามข้อต่อต่างๆ
A12: 5.ตรวจเช็คทำความสะอาดยางขอบประตูและข้อต่อของระบบเปิดปิดประตู
A13: 6.ตรวจเช็คและทำความสะอาดหม้อต้มผลิตไอน้ำ
A14: 7.ตรวจสอบการทำงานของ vacuum pump และระดับการ vacuum
A15: 8.ตรวจเช็คระบบควบคุมทุกตัว, ย้ำสายไฟตามจุดต่อสายต่างๆ
A16: 9.ตรวจเช็คการทำงานของระบบ Pneumatic valve และระดับน้ำมัน Hydraulic
A17: 10.ตรวจสอบแรงดันและอุณหภูมิของโปรแกรมที่ทำงานจริง
A18: หัวข้อการบำรุงรักษาโดยบริษัททุก 1 ปี
A19: 11.เปลี่ยน Sterile air filter

Sheet List AC6
A1: รายการบำรุงรักษา | B1: Cleanroom
A2: ชื่อเครื่องมือ | B2: เครื่องผลิตอากาศอัด | H2: รหัส | I2: - | M2: สถานที่ | O2: ห้องปั๊มลม ชั้น 6 | T2: ปี | U2: 2566 | W2: ผู้รับผิดชอบ | Z2: บ. U Social Autom.
A4: ราย | B4: ความถี่
A7: - เปลี่ยนไส้กรอง Air inlet filter และ filter inline | B7: 1 ปี
A8: - เปลี่ยนสายพาน V belt และเช็ควาล์ว | B8: 2 ปี
A9: - ทำความสะอาดพัดลม ท่อพัดลม และแผงระบายความร้อน | B9: 2 ปี
A10: - หล่อลื่นแบริ่งสโครลตัวล่างที่เคลื่อนที่ | B10: 2 ปี
A11: - เปลี่ยนท่อขาออกและพลาสติกภายในท่อ | B11: 4 ปี
A12: - หล่อลื่นแบริ่งขาข้อเหวี่ยง (pin crank) | B12: 4 ปี
A13: - เปลี่ยนซีลตางๆ Tip seals dust seal และ inlet seal | B13: 4 ปี
